<?xml version="0.0" ?>
<robot name="urdf_box">

  <joint name="jointworld" type="prismatic">
    <parent link="world"/>
    <child link="link0"/>
    <origin rpy="0.00000 -0.00000 0.00000" xyz="0.00000 0.00000 0.00000"/>
    <axis xyz="0.00000 0.00000 1.00000"/>
  </joint>

  <joint name="joint01" type="fixed">
    <parent link="link0"/>
    <child link="link1"/>
    <origin rpy="0.00000 0.00000 0.00000" xyz="0.00000 0.00000 0.00000"/>
    <axis xyz="1.00000 0.00000 0.00000"/>
  </joint>

  <joint name="joint02" type="fixed">
    <parent link="link0"/>
    <child link="link2"/>
    <origin rpy="0.00000 0.00000 0.00000" xyz="0.00000 0.00000 0.00000"/>
    <axis xyz="1.00000 0.00000 0.00000"/>
  </joint>

  <joint name="joint13" type="prismatic">
    <parent link="link1"/>
    <child link="link3"/>
    <origin rpy="0.00000 0.00000 0.00000" xyz="1.00000 0.00000 0.00000"/>
    <axis xyz="1.00000 0.00000 0.00000"/>
  </joint>

  <joint name="joint24" type="prismatic">
    <parent link="link2"/>
    <child link="link4"/>
    <origin rpy="0.00000 0.00000 0.00000" xyz="1.00000 0.00000 0.00000"/>
    <axis xyz="-1.00000 0.00000 0.00000"/>
  </joint>

  <link name="world">
    <inertial>
      <origin rpy="0.00000 -0.00000 0.00000" xyz="0.00000 0.00000 0.00000"/>
      <mass value="0.00000"/>
      <inertia ixx="0.00000" ixy="0" ixz="0" iyy="0.00000" iyz="0" izz="0.00000"/>
    </inertial>
  </link>

  <link name="link0">
    <inertial>
      <origin rpy="0.00000 -0.00000 0.00000" xyz="0.00000 0.00000 0.00000"/>
      <mass value="0.00000"/>
      <inertia ixx="0.00000" ixy="0" ixz="0" iyy="0.00000" iyz="0" izz="0.00000"/>
    </inertial>
  </link>

  <link name="link1">
    <inertial>
      <origin rpy="0.00000 -0.00000 0.00000" xyz="0.00000 0.00000 0.00000"/>
      <mass value="0.00000"/>
      <inertia ixx="0.00000" ixy="0" ixz="0" iyy="0.00000" iyz="0" izz="0.00000"/>
    </inertial>
  </link>

  <link name="link2">
    <inertial>
      <origin rpy="0.00000 -0.00000 0.00000" xyz="0.00000 0.00000 0.00000"/>
      <mass value="0.00000"/>
      <inertia ixx="0.00000" ixy="0" ixz="0" iyy="0.00000" iyz="0" izz="0.00000"/>
    </inertial>
  </link>


  <link name="link3">
    <contact>
      <friction_anchor/>
      <stiffness value="300.0"/>
      <damping value="10000.0"/>
      <spinning_friction value="0.1"/>
      <lateral_friction value="1.0"/>
    </contact>

    <inertial>
      <origin rpy="0 0 0" xyz="0 0 0"/>
       <mass value="10.0"/>
       <inertia ixx="1" ixy="0" ixz="0" iyy="1" iyz="0" izz="1"/>
    </inertial>
    <visual>
      <origin rpy="0 0 0" xyz="0 0 0"/>
      <geometry>
                <mesh filename="cube.obj" scale="1 1 1"/>      
      </geometry>
      <material name="white">
        <color rgba="1 1 1 1"/>
        <specular rgb="11 1 1"/>
      </material>
    </visual>
    <collision>
      <origin rpy="0 0 0" xyz="0 0 0"/>
      <geometry>
        <box size="0.5 0.5 0.5"/>
      </geometry>
    </collision>
  </link>

  <link name="link4">
    <contact>
      <friction_anchor/>
      <stiffness value="300.0"/>
      <damping value="10000.0"/>
      <spinning_friction value="0.1"/>
      <lateral_friction value="1.0"/>
    </contact>

    <inertial>
      <origin rpy="0 0 0" xyz="0 0 0"/>
       <mass value="10.0"/>
       <inertia ixx="1" ixy="0" ixz="0" iyy="1" iyz="0" izz="1"/>
    </inertial>
    <visual>
      <origin rpy="0 0 0" xyz="0 0 0"/>
      <geometry>
                <mesh filename="cube.obj" scale="1 1 1"/>      
      </geometry>
      <material name="white">
        <color rgba="1 1 1 1"/>
        <specular rgb="11 1 1"/>
      </material>
    </visual>
    <collision>
      <origin rpy="0 0 0" xyz="0 0 0"/>
      <geometry>
        <box size="0.5 0.5 0.5"/>
      </geometry>
    </collision>
  </link>


</robot>

