<mujoco model="ant">
  <compiler angle="degree" coordinate="local" inertiafromgeom="false"/>
  <option integrator="RK4" timestep="0.01"/>
  <custom>
    <numeric data="0.0 0.0 0.55 1.0 0.0 0.0 0.0 0.0 1.0 0.0 -1.0 0.0 -1.0 0.0 1.0" name="init_qpos"/>
  </custom>
  <default>
    <joint armature="0" damping="1" limited="true"/>
    <geom conaffinity="0" condim="3" density="5.0" friction="1. 0. 0." margin="0.01" rgba="0.8 0.6 0.4 1"/>
  </default>
  <worldbody>
    <geom conaffinity="1" condim="3" name="floor" pos="0 0 0" rgba="0.8 0.9 0.8 1" size="40 40 40" type="plane"/>
    <body name="torso" pos="0 0 0.75">
      <geom name="torso_geom" pos="0 0 0" size="0.25" type="sphere"/>
      <inertial pos="0 0 0" euler="0 0 0" mass=".32724925" diaginertia=".00818125 .00818125 .00818125"/>
      <joint armature="0" damping="0" limited="false" margin="0.01" name="root" pos="0 0 0" type="free"/>
      <body name="front_left_leg" pos="0 0 0">
        <geom fromto="0.0 0.0 0.0 0.2 0.2 0.0" name="aux_1_geom" size="0.08" type="capsule" rgba=".8 .5 .3 1"/>
        <inertial pos="0.1 0.1 0" euler="-1.57080 0.78540 -0.78540" mass="1.03915775" diaginertia="1.00089755 1.00089755 1.00146095"/>
        <body name="aux_1" pos="0.2 0.2 0">
          <joint axis="0 0 1" name="hip_1" pos="0.0 0.0 0.0" range="-40 40" type="hinge"/>
          <geom fromto="0.0 0.0 0.0 0.2 0.2 0.0" name="left_leg_geom" size="0.08" type="capsule" rgba=".8 .5 .3 1"/>
          <inertial pos="0.1 0.1 0" euler="-1.57080 0.78540 -0.78540" mass="1.03915775" diaginertia="1.00089755 1.00089755 1.00146095"/>
          <body pos="0.2 0.2 0" name="front_left_foot">
            <joint axis="-1 1 0" name="ankle_1" pos="0.0 0.0 0.0" range="30 100" type="hinge"/>
            <geom fromto="0.0 0.0 0.0 0.4 0.4 0.0" name="left_ankle_geom" size="0.08" type="capsule" rgba=".8 .5 .3 1"/>
            <inertial pos="0.2 0.2 0" euler="-1.57080 0.78540 -0.78540" mass="1.0675922" diaginertia="1.00284065 1.00284065 1.0051045"/>
          </body>
        </body>
      </body>
      <body name="front_right_leg" pos="0 0 0">
        <geom fromto="0.0 0.0 0.0 -0.2 0.2 0.0" name="aux_2_geom" size="0.08" type="capsule"/>
        <inertial pos="-0.1 0.1 0" euler="-1.57080 -0.78540 0.78540" mass="1.03915775" diaginertia="1.00089755 1.00089755 1.00146095"/>
        <body name="aux_2" pos="-0.2 0.2 0">
          <joint axis="0 0 1" name="hip_2" pos="0.0 0.0 0.0" range="-40 40" type="hinge"/>
          <geom fromto="0.0 0.0 0.0 -0.2 0.2 0.0" name="right_leg_geom" size="0.08" type="capsule"/>
          <inertial pos="-0.1 0.1 0" euler="-1.57080 -0.78540 0.78540" mass="1.03915775" diaginertia="1.00089755 1.00089755 1.00146095"/>
          <body pos="-0.2 0.2 0" name="front_right_foot">
            <joint axis="1 1 0" name="ankle_2" pos="0.0 0.0 0.0" range="-100 -30" type="hinge"/>
            <geom fromto="0.0 0.0 0.0 -0.4 0.4 0.0" name="right_ankle_geom" size="0.08" type="capsule"/>
            <inertial pos="-0.2 0.2 0" euler="-1.57080 -0.78540 0.78540" mass="1.0675922" diaginertia="1.00284065 1.00284065 1.0051045"/>
          </body>
        </body>
      </body>
      <body name="left_back_leg" pos="0 0 0">
        <geom fromto="0.0 0.0 0.0 -0.2 -0.2 0.0" name="aux_3_geom" size="0.08" type="capsule"/>
        <inertial pos="-0.1 -0.1 0" euler="1.57080 -0.78540 -0.78540" mass="1.03915775" diaginertia="1.00089755 1.00089755 1.00146095"/>
        <body name="aux_3" pos="-0.2 -0.2 0">
          <joint axis="0 0 1" name="hip_3" pos="0.0 0.0 0.0" range="-40 40" type="hinge"/>
          <geom fromto="0.0 0.0 0.0 -0.2 -0.2 0.0" name="back_leg_geom" size="0.08" type="capsule"/>
          <inertial pos="-0.1 -0.1 0" euler="1.57080 -0.78540 -0.78540" mass="1.03915775" diaginertia="1.00089755 1.00089755 1.00146095"/>
          <body pos="-0.2 -0.2 0" name="left_back_foot">
            <joint axis="-1 1 0" name="ankle_3" pos="0.0 0.0 0.0" range="-100 -30" type="hinge"/>
            <geom fromto="0.0 0.0 0.0 -0.4 -0.4 0.0" name="third_ankle_geom" size="0.08" type="capsule"/>
            <inertial pos="-0.2 -0.2 0" euler="1.57080 -0.78540 -0.78540" mass="1.0675922" diaginertia="1.00284065 1.00284065 1.0051045"/>
          </body>
        </body>
      </body>
      <body name="right_back_leg" pos="0 0 0">
        <geom fromto="0.0 0.0 0.0 0.2 -0.2 0.0" name="aux_4_geom" size="0.08" type="capsule" rgba=".8 .5 .3 1"/>
        <inertial pos="0.1 -0.1 0" euler="1.57080 0.78540 0.78540" mass="1.03915775" diaginertia="1.00089755 1.00089755 1.00146095"/>
        <body name="aux_4" pos="0.2 -0.2 0">
          <joint axis="0 0 1" name="hip_4" pos="0.0 0.0 0.0" range="-40 40" type="hinge"/>
          <geom fromto="0.0 0.0 0.0 0.2 -0.2 0.0" name="rightback_leg_geom" size="0.08" type="capsule" rgba=".8 .5 .3 1"/>
          <inertial pos="0.1 -0.1 0" euler="1.57080 0.78540 0.78540" mass="1.03915775" diaginertia="1.00089755 1.00089755 1.00146095"/>
          <body pos="0.2 -0.2 0" name="right_back_foot">
            <joint axis="1 1 0" name="ankle_4" pos="0.0 0.0 0.0" range="30 100" type="hinge"/>
            <geom fromto="0.0 0.0 0.0 0.4 -0.4 0.0" name="fourth_ankle_geom" size="0.08" type="capsule" rgba=".8 .5 .3 1"/>
            <inertial pos="0.2 -0.2 0" euler="1.57080 0.78540 0.78540" mass="1.0675922" diaginertia="1.00284065 1.00284065 1.0051045"/>
          </body>
        </body>
      </body>
    </body>
  </worldbody>
  <actuator>
    <motor ctrllimited="true" ctrlrange="-1.0 1.0" joint="hip_4" gear="150"/>
    <motor ctrllimited="true" ctrlrange="-1.0 1.0" joint="ankle_4" gear="150"/>
    <motor ctrllimited="true" ctrlrange="-1.0 1.0" joint="hip_1" gear="150"/>
    <motor ctrllimited="true" ctrlrange="-1.0 1.0" joint="ankle_1" gear="150"/>
    <motor ctrllimited="true" ctrlrange="-1.0 1.0" joint="hip_2" gear="150"/>
    <motor ctrllimited="true" ctrlrange="-1.0 1.0" joint="ankle_2" gear="150"/>
    <motor ctrllimited="true" ctrlrange="-1.0 1.0" joint="hip_3" gear="150"/>
    <motor ctrllimited="true" ctrlrange="-1.0 1.0" joint="ankle_3" gear="150"/>
  </actuator>
</mujoco>